<?xml version="1.0"?>
<robot name="barista_robot">     
    
    <material name="red">
      <color rgba="1.0 0.0 0.0 1"/>
    </material>

    <material name="white">
      <color rgba="1.0 1.0 1.0 1"/>
    </material>

    <material name="black">
      <color rgba="0.0 0.0 0.0 1"/>
    </material>

    <material name="green_light">
        <color rgba="0.0 1.0 0.0 1"/>
    </material>

    <material name="green_dark">
        <color rgba="0.0 0.5 0.0 1"/>
    </material>

    <material name="blue">
        <color rgba="0.0 0.0 1.0 1"/>
    </material>
    
    <link name="base_link"></link>

    <!-- Body -->
    <link name="chassis">
        <visual>
            <origin rpy="0 0 0" xyz="0 0 0"/>
                <geometry>
                    <cylinder length="0.155" radius="0.178"/>
                </geometry>
            <material name="blue"/>
        </visual>

        <collision>
        <geometry>
            <cylinder length="0.155" radius="0.178"/>
        </geometry>
        </collision>

        <inertial>
            <mass value="2.5"/>
            <origin rpy="0 0 0" xyz="0 0 0"/>
            <inertia ixx="0.024807708333333334" ixy="0" ixz="0" iyy="0.024807708333333334" iyz="0" izz="0.039604999999999994"/>
        </inertial>

    </link>

    <joint name="base_link_joint" type="fixed">
        <origin rpy="0 0 0" xyz="0 0 0.1127" />
        <parent link="base_link" />
        <child link="chassis" />
    </joint>

    <gazebo reference="chassis">
        <material>Gazebo/Blue</material>
    </gazebo>

    <!--Right Motor Wheel-->
    <link name="right_motor_wheel">
        <visual>
            <origin rpy="0 1.5707 1.5707" xyz="0 0 0"/>
                <geometry>
                    <cylinder length="0.0206" radius="0.0352"/>
                </geometry>
            <material name="black"/>
        </visual>

        <collision>
            <origin rpy="0 1.5707 1.5707" xyz="0 0 0"/>
            <geometry>
                <cylinder length="0.0206" radius="0.0352"/>
            </geometry>
        </collision>

        <inertial>
            <mass value="0.1"/>
            <origin rpy="0 1.5707 1.5707" xyz="0 0 0"/>
            <inertia ixx="3.451233333333334e-05" ixy="0" ixz="0" iyy="3.451233333333334e-05" iyz="0" izz="6.1952e-05"/>
        </inertial>

    </link>

    <joint name="right_motor_wheel_joint" type="continuous">
        <origin rpy="0 0 0" xyz="0 -0.158 0.0352" />
        <parent link="base_link" />
        <child link="right_motor_wheel" />
        <axis rpy="0 0 0" xyz="0 1 0"/>
        <limit effort="10000" velocity="1000"/>
        <joint_properties damping="1.0" friction="1.0"/>
    </joint>

    <gazebo reference="right_motor_wheel">
        <mu1>0.7</mu1>
        <mu2>0.7</mu2>
        <material>Gazebo/Black</material>
    </gazebo>


    <!--Left Motor Wheel-->
    <link name="left_motor_wheel">
        <visual>
            <origin rpy="0 1.5707 1.5707" xyz="0 0 0"/>
                <geometry>
                    <cylinder length="0.0206" radius="0.0352"/>
                </geometry>
            <material name="black"/>
        </visual>

        <collision>
             <origin rpy="0 1.5707 1.5707" xyz="0 0 0"/>
            <geometry>
                <cylinder length="0.0206" radius="0.0352"/>
            </geometry>
        </collision>

        <inertial>
            <mass value="0.1"/>
            <origin rpy="0 1.5707 1.5707" xyz="0 0 0"/>
            <inertia ixx="3.451233333333334e-05" ixy="0" ixz="0" iyy="3.451233333333334e-05" iyz="0" izz="6.1952e-05"/>
        </inertial>

    </link>

    <joint name="left_motor_wheel_joint" type="continuous">
        <origin rpy="0 0 0" xyz="0 0.158 0.0352" />
        <parent link="base_link" />
        <child link="left_motor_wheel" />
        <axis rpy="0 0 0" xyz="0 1 0"/>
        <limit effort="10000" velocity="1000"/>
        <joint_properties damping="1.0" friction="1.0"/>
    </joint>

    <gazebo reference="left_motor_wheel">
        <mu1>0.7</mu1>
        <mu2>0.7</mu2>
        <material>Gazebo/Black</material>
    </gazebo>

    <!-- Caster Wheel Front -->
    <link name="front_yaw_link">
        <visual>
            <origin rpy="0 1.5707 1.5707" xyz="0 0 0"/>
            <geometry>
                <cylinder length="0.05" radius="0.0152"/>
            </geometry>
            <material name="blue"/>
        </visual>

        <collision>
            <origin rpy="0 1.5707 1.5707" xyz="0 0 0"/>
            <geometry>
                <cylinder length="0.05" radius="0.0152"/>
            </geometry>
        </collision>

        <inertial>
            <mass value="0.01"/>
            <origin rpy="0 1.5707 1.5707" xyz="0 0 0"/>
            <inertia ixx="2.660933333333334e-06" ixy="0" ixz="0" iyy="2.660933333333334e-06" iyz="0" izz="1.1552000000000002e-06"/>
        </inertial>
    </link>

    <joint name="front_yaw_joint" type="continuous">
        <origin rpy="0 0 0" xyz="0.128 0 0.0352" />
        <parent link="base_link" />
        <child link="front_yaw_link" />
        <axis xyz="0 0 1" />
        <limit effort="1000.0" velocity="100.0" />
        <dynamics damping="0.0" friction="0.1"/>
    </joint>

    <link name="front_roll_link">
        <visual>
            <origin rpy="0 1.5707 1.5707" xyz="0 0 0"/>
            <geometry>
            <cylinder length="0.05" radius="0.0152"/>
            </geometry>
            <material name="red"/>
        </visual>

        <collision>
            <origin rpy="0 1.5707 1.5707" xyz="0 0 0"/>
            <geometry>
                <cylinder length="0.05" radius="0.0152"/>
            </geometry>
        </collision>

        <inertial>
            <mass value="0.01"/>
            <origin rpy="0 1.5707 1.5707" xyz="0 0 0"/>
            <inertia ixx="2.660933333333334e-06" ixy="0" ixz="0" iyy="2.660933333333334e-06" iyz="0" izz="1.1552000000000002e-06"/>
        </inertial>
    </link>

    <joint name="front_roll_joint" type="continuous">
        <origin rpy="0 0 0" xyz="0 0 0" />
        <parent link="front_yaw_link" />
        <child link="front_roll_link" />
        <axis xyz="1 0 0" />
        <limit effort="1000.0" velocity="100.0" />
        <dynamics damping="0.0" friction="0.1"/>
    </joint>

    <link name="front_pitch_link">
        <visual>
            <origin rpy="0 1.5707 1.5707" xyz="0 0 0"/>
            <geometry>
                <sphere radius="0.0352"/>
            </geometry>
            <material name="green_dark"/>
        </visual>

        <collision>
            <origin rpy="0 1.5707 1.5707" xyz="0 0 0"/>
            <geometry>
                 <sphere radius="0.0352"/>
            </geometry>
        </collision>

        <inertial>
            <mass value="0.1"/>
            <origin rpy="0 1.5707 1.5707" xyz="0 0 0"/>
            <inertia ixx="4.95616e-05" ixy="0" ixz="0" iyy="4.95616e-05" iyz="0" izz="4.95616e-05"/>
        </inertial>
    </link>

    <joint name="front_pitch_joint" type="continuous">
        <origin rpy="0 0 0" xyz="0 0 0" />
        <parent link="front_roll_link" />
        <child link="front_pitch_link" />
        <axis xyz="0 1 0" />
        <limit effort="1000.0" velocity="100.0" />
        <dynamics damping="0.0" friction="0.1"/>
    </joint>

    <gazebo reference="front_pitch_link">
        <mu1>0.0</mu1>
        <mu2>0.0</mu2>
        <material>Gazebo/Green</material>
    </gazebo>

    <!-- Caster Wheel Back -->
    <link name="back_yaw_link">
        <visual>
            <origin rpy="0 1.5707 1.5707" xyz="0 0 0"/>
            <geometry>
                <cylinder length="0.05" radius="0.0152"/>
            </geometry>
            <material name="blue"/>
        </visual>
        <collision>
            <origin rpy="0 1.5707 1.5707" xyz="0 0 0"/>
            <geometry>
                <cylinder length="0.05" radius="0.0152"/>
            </geometry>
        </collision>
        <inertial>
            <mass value="0.1"/>
            <origin rpy="0 1.5707 1.5707" xyz="0 0 0"/>
            <inertia ixx="2.660933333333334e-06" ixy="0" ixz="0" iyy="2.660933333333334e-06" iyz="0" izz="1.1552000000000002e-06"/>
        </inertial>
    </link>

    <joint name="back_yaw_joint" type="continuous">
        <origin rpy="0 0 0" xyz="-0.128 0 0.0352" />
        <parent link="base_link" />
        <child link="back_yaw_link" />
        <axis xyz="0 0 1" />
        <limit effort="1000.0" velocity="100.0" />
        <dynamics damping="0.0" friction="0.1"/>
    </joint>

    <link name="back_roll_link">
        <visual>
            <origin rpy="0 1.5707 1.5707" xyz="0 0 0"/>
            <geometry>
                <cylinder length="0.05" radius="0.0152"/>
            </geometry>
            <material name="red"/>
        </visual>

        <collision>
            <origin rpy="0 1.5707 1.5707" xyz="0 0 0"/>
            <geometry>
                <cylinder length="0.05" radius="0.0152"/>
            </geometry>
        </collision>

        <inertial>
            <mass value="0.1"/>
            <origin rpy="0 1.5707 1.5707" xyz="0 0 0"/>
            <inertia ixx="2.660933333333334e-06" ixy="0" ixz="0" iyy="2.660933333333334e-06" iyz="0" izz="1.1552000000000002e-06"/>
        </inertial>
    </link>

    <joint name="back_roll_joint" type="continuous">
        <origin rpy="0 0 0" xyz="0 0 0" />
        <parent link="back_yaw_link" />
        <child link="back_roll_link" />
        <axis xyz="1 0 0" />
        <limit effort="1000.0" velocity="100.0" />
        <dynamics damping="0.0" friction="0.1"/>
    </joint>

    <link name="back_pitch_link">
        <visual>
            <origin rpy="0 1.5707 1.5707" xyz="0 0 0"/>
            <geometry>
                <sphere radius="0.0352"/>
            </geometry>
            <material name="green_dark"/>
        </visual>
        <collision>
            <origin rpy="0 1.5707 1.5707" xyz="0 0 0"/>
            <geometry>
                <sphere radius="0.0352"/>
            </geometry>
        </collision>

        <inertial>
            <mass value="0.1"/>
            <origin rpy="0 1.5707 1.5707" xyz="0 0 0"/>
            <inertia ixx="4.95616e-05" ixy="0" ixz="0" iyy="4.95616e-05" iyz="0" izz="4.95616e-05"/>
        </inertial>
    </link>

    <joint name="back_pitch_joint" type="continuous">
        <origin rpy="0 0 0" xyz="0 0 0" />
        <parent link="back_roll_link" />
        <child link="back_pitch_link" />
        <axis xyz="0 1 0" />
        <limit effort="1000.0" velocity="100.0" />
        <dynamics damping="0.0" friction="0.1"/>
    </joint>

    <gazebo reference="back_pitch_link">
        <mu1>0.0</mu1>
        <mu2>0.0</mu2>
        <material>Gazebo/Green</material>
    </gazebo>
    <gazebo reference="back_roll_link">
        <material>Gazebo/Red</material>
    </gazebo>
    <gazebo reference="back_yaw_link">
        <material>Gazebo/Blue</material>
    </gazebo>


    <!--Front Right Rod-->
    <link name="front_right_rod">
        <visual>
            <origin rpy="0 0 0" xyz="0 0 0.110"/>
                <geometry>
                    <cylinder length="0.220" radius="0.01"/>
                </geometry>
            <material name="white"/>
        </visual>

        <collision>
            <origin rpy="0 0 0" xyz="0 0 0.110"/>
            <geometry>
                <cylinder length="0.220" radius="0.01"/>
            </geometry>
        </collision>

        <inertial>
            <mass value="0.250"/>
            <origin rpy="0 0 0" xyz="0 0 0.110"/>
            <inertia ixx="0.0010145833333333333" ixy="0" ixz="0" iyy="0.0010145833333333333" iyz="0" izz="1.25e-05"/>
        </inertial>

    </link>

    <joint name="front_right_rod_joint" type="fixed">
        <origin rpy="0 0 0" xyz="0.050 -0.130 0.1902" /> <!--z = 0.155 + 0.0352-->
        <parent link="base_link" />
        <child link="front_right_rod" />
    </joint>

    <gazebo reference="front_right_rod">
        <material>Gazebo/White</material>
    </gazebo>


    <!--Front Left Rod-->
    <link name="front_left_rod">
        <visual>
            <origin rpy="0 0 0" xyz="0 0 0.110"/>
                <geometry>
                    <cylinder length="0.220" radius="0.01"/>
                </geometry>
            <material name="white"/>
        </visual>

        <collision>
            <origin rpy="0 0 0" xyz="0 0 0.110"/>
            <geometry>
                <cylinder length="0.220" radius="0.01"/>
            </geometry>
        </collision>

        <inertial>
            <mass value="0.250"/>
            <origin rpy="0 0 0" xyz="0 0 0.110"/>
            <inertia ixx="0.0010145833333333333" ixy="0" ixz="0" iyy="0.0010145833333333333" iyz="0" izz="1.25e-05"/>
        </inertial>

    </link>

    <joint name="front_left_rod_joint" type="fixed">
        <origin rpy="0 0 0" xyz="0.050 0.130 0.1902" />
        <parent link="base_link" />
        <child link="front_left_rod" />
    </joint>

    <gazebo reference="front_left_rod">
        <material>Gazebo/White</material>
    </gazebo>

    <!--Back Right Rod-->
    <link name="back_right_rod">
        <visual>
            <origin rpy="0 0 0" xyz="0 0 0.110"/>
            <geometry>
                <cylinder length="0.220" radius="0.01"/>
            </geometry>
            <material name="white"/>
        </visual>

        <collision>
            <origin rpy="0 0 0" xyz="0 0 0.110"/>
            <geometry>
                <cylinder length="0.220" radius="0.01"/>
            </geometry>
        </collision>

        <inertial>
            <mass value="0.250"/>
            <origin rpy="0 0 0" xyz="0 0 0.110"/>
            <inertia ixx="0.0010145833333333333" ixy="0" ixz="0" iyy="0.0010145833333333333" iyz="0" izz="1.25e-05"/>
        </inertial>

    </link>

    <joint name="back_right_rod_joint" type="fixed">
        <origin rpy="0 0 0" xyz="-0.020 -0.130 0.1902" />
        <parent link="base_link" />
        <child link="back_right_rod" />
    </joint>

    <gazebo reference="back_right_rod">
        <material>Gazebo/White</material>
    </gazebo>

    <!--Back Left Rod-->
    <link name="back_left_rod">
        <visual>
            <origin rpy="0 0 0" xyz="0 0 0.110"/>
                <geometry>
                    <cylinder length="0.220" radius="0.01"/>
                </geometry>
            <material name="white"/>
        </visual>

        <collision>
            <origin rpy="0 0 0" xyz="0 0 0.110"/>
            <geometry>
                <cylinder length="0.220" radius="0.01"/>
            </geometry>
        </collision>

        <inertial>
            <mass value="0.250"/>
            <origin rpy="0 0 0" xyz="0 0 0.110"/>
            <inertia ixx="0.0010145833333333333" ixy="0" ixz="0" iyy="0.0010145833333333333" iyz="0" izz="1.25e-05"/>
        </inertial>

    </link>

    <joint name="back_left_rod_joint" type="fixed">
        <origin rpy="0 0 0" xyz="-0.020 0.130 0.1902" />
        <parent link="base_link" />
        <child link="back_left_rod" />
    </joint>

    <gazebo reference="back_left_rod">
        <material>Gazebo/White</material>
    </gazebo>

    <!--Cup holder-->
    <link name="cup_holder">
        <visual>
            <origin rpy="0 0 0" xyz="0 0 0"/>
                <geometry>
                    <cylinder length="0.090" radius="0.160"/>
                </geometry>
            <material name="blue"/>
        </visual>

        <collision>
            <geometry>
                <cylinder length="0.090" radius="0.160"/>
            </geometry>
        </collision>

        <inertial>
            <mass value="1.0"/>
            <origin rpy="0 0 0" xyz="0 0 0"/>
            <inertia ixx="0.007075" ixy="0" ixz="0" iyy="0.007075" iyz="0" izz="0.0128"/>
        </inertial>

    </link>

    <!-- The cup holder is fixed to the robot body-->
    <joint name="cup_holder_joint" type="fixed">
        <origin rpy="0 0 0" xyz="0 0 0.4552" /> <!--z = 0.03552 + 0.155 + 0.220 + (0.090/2) -->
        <parent link="base_link" />
        <child link="cup_holder" />
    </joint>

    <gazebo reference="cup_holder">
        <material>Gazebo/Blue</material>
    </gazebo>

    <!-- Laser Position Control-->
    <!--Laser specs : https://www.hokuyo-aut.jp/search/single.php?serial=166#spec -->
    <link name="laser_scan_link">
        <visual>
            <origin rpy="0 0 0" xyz="0 0 -0.04"/>
            <geometry>
                <mesh filename="package://barista_robot_description/meshes/hokuyo_urg_04lx.dae" scale="1.0 1.0 1.0"/>
            </geometry>
        </visual>

        <collision>
            <origin rpy="0 0 0" xyz="0 0 0"/>
            <geometry>
                <box size="0.1 0.1 0.08"/>
            </geometry>
        </collision>

        <inertial>
            <mass value="0.160"/>
            <origin rpy="0 0 0" xyz="0 0 0"/>
            <inertia ixx="0.0002186666666666667" ixy="0" ixz="0" iyy="0.0002186666666666667" iyz="0" izz="0.00026666666666666673"/>
        </inertial>
    </link>


    <joint name="laser_scan_link_joint" type="fixed">
        <origin rpy="0 0 0" xyz="0.110 0 0.2302"/> <!--z = 0.0352 + 0.155 + 0.08/2-->
        <parent link="base_link"/>
        <child link="laser_scan_link"/>
    </joint>


    <gazebo reference="laser_scan_link">
        <material>Gazebo/Grey</material>
        <sensor name="lidar_sensor" type="ray">
            <!-- <pose>0 0 0 0 0 0</pose> -->
            <always_on>true</always_on>
            <visualize>true</visualize>
            <update_rate>15.0</update_rate>
            <ray>
                <scan>
                    <horizontal>
                        <samples>200</samples>
                        <resolution>1</resolution>
                        <min_angle>-1.5707</min_angle>
                        <max_angle>1.5707</max_angle>
                    </horizontal>
                </scan>
                <range>
                    <min>0.2</min>
                    <max>30.0</max>
                    <resolution>0.01</resolution>
                </range>
                <noise>
                    <type>gaussian</type>
                    <mean>0.0</mean>
                    <stddev>0.01</stddev>
				</noise>
            </ray>
            <plugin name="laser_controller" filename="libgazebo_ros_ray_sensor.so">
                <ros>
                    <remapping>~/out:=scan</remapping>
                </ros>
                <frame_name>laser_scan_link</frame_name>
                <output_type>sensor_msgs/LaserScan</output_type>
            </plugin>
        </sensor>
   </gazebo>


    <gazebo>
        <plugin name="barista_bot_joint_state" filename="libgazebo_ros_joint_state_publisher.so">
            <ros>
                <remapping>~/out:=joint_states</remapping>
            </ros>
            <update_rate>30</update_rate>
            <joint_name>right_motor_wheel_joint</joint_name>
            <joint_name>left_motor_wheel_joint</joint_name>
            <joint_name>front_yaw_joint</joint_name>
            <joint_name>back_yaw_joint</joint_name>
            <joint_name>front_roll_joint</joint_name>
            <joint_name>back_roll_joint</joint_name>
            <joint_name>front_pitch_joint</joint_name>
            <joint_name>back_pitch_joint</joint_name>
        </plugin>
    </gazebo>


   <gazebo>
        <plugin filename="libgazebo_ros_diff_drive.so" name="differential_drive_controller">

            <!-- wheels -->
            <left_joint>left_motor_wheel_joint</left_joint>
            <right_joint>right_motor_wheel_joint</right_joint>

            <!-- kinematics -->
            <wheel_separation>0.316</wheel_separation> <!--w_s = 0.158 - (-0.158)-->
            <wheel_diameter>0.0704</wheel_diameter> <!--w_d = 0.0352 * 2 -->

            <!-- limits -->
            <max_wheel_torque>1.0</max_wheel_torque>
            <max_wheel_acceleration>2.0</max_wheel_acceleration>
            
            <!-- Topic to receive geometry_msgs/Twist message commands, defaults to `cmd_vel` -->
            <commandTopic>cmd_vel</commandTopic>

            <!-- output -->
            <publish_odom>true</publish_odom>
            <publish_odom_tf>true</publish_odom_tf>
            <odometry_frame>odom</odometry_frame>
            <robot_base_frame>base_link</robot_base_frame>


        </plugin>
    </gazebo>


</robot>